<?xml version="1.0" encoding="utf-8" ?>
<!-- This URDF was automatically created by SolidWorks to URDF Exporter! Originally created by Stephen Brawner (brawner@gmail.com) 
     Commit Version: 1.6.0-4-g7f85cfe  Build Version: 1.6.7995.38578
     For more information, please see http://wiki.ros.org/sw_urdf_exporter -->
<robot name="robot_arm">
    <link name="base_link">
        <inertial>
            <origin xyz="-0.000379135468760089 0.00044051065817062 0.025023985175857" rpy="0 0 0" />
            <mass value="0.195490498054091" />
            <inertia ixx="0.000197098942378015" ixy="1.73544380326031E-08" ixz="-1.8002259724736E-07" iyy="0.00020115978920217" iyz="-2.1699799937825E-06" izz="0.000316589137651227" />
        </inertial>
        <visual>
            <origin xyz="0 0 0" rpy="0 0 0" />
            <geometry>
                <mesh filename="package://robot_arm/meshes/base_link.STL" />
            </geometry>
            <material name="">
                <color rgba="0 1 0 1" />
            </material>
        </visual>
        <collision>
            <origin xyz="0 0 0" rpy="0 0 0" />
            <geometry>
                <mesh filename="package://robot_arm/meshes/base_link.STL" />
            </geometry>
        </collision>
    </link>
    <link name="Link_1">
        <inertial>
            <origin xyz="0.00458971266849917 -3.20046849174062E-05 0.0425574520928825" rpy="0 0 0" />
            <mass value="0.31284736542166" />
            <inertia ixx="0.000154646806877315" ixy="4.09236809944852E-09" ixz="-8.1373895526861E-06" iyy="0.000137640315457541" iyz="-1.10068804835806E-08" izz="0.000167440749331112" />
        </inertial>
        <visual>
            <origin xyz="0 0 0" rpy="0 0 0" />
            <geometry>
                <mesh filename="package://robot_arm/meshes/Link_1.STL" />
            </geometry>
            <material name="">
                <color rgba="0.43921568627451 0.43921568627451 0.43921568627451 1" />
            </material>
        </visual>
        <collision>
            <origin xyz="0 0 0" rpy="0 0 0" />
            <geometry>
                <mesh filename="package://robot_arm/meshes/Link_1.STL" />
            </geometry>
        </collision>
    </link>
    <joint name="Joint_1" type="revolute">
        <origin xyz="0 0 0.063" rpy="0 0 0" />
        <parent link="base_link" />
        <child link="Link_1" />
        <axis xyz="0 0 -1" />
        <limit lower="-3.14" upper="3.14" effort="100" velocity="100" />
    </joint>
    <link name="Link_2">
        <inertial>
            <origin xyz="0.0437291888718274 -3.17241634150665E-05 0.121342621403178" rpy="0 0 0" />
            <mass value="0.587907106128444" />
            <inertia ixx="0.000432111071621861" ixy="3.77302870663473E-09" ixz="-5.21839747889797E-10" iyy="0.000377843479563513" iyz="-1.33160548801769E-08" izz="0.000325262257620724" />
        </inertial>
        <visual>
            <origin xyz="0 0 0" rpy="0 0 0" />
            <geometry>
                <mesh filename="package://robot_arm/meshes/Link_2.STL" />
            </geometry>
            <material name="">
                <color rgba="0.576470588235294 0.396078431372549 0.749019607843137 1" />
            </material>
        </visual>
        <collision>
            <origin xyz="0 0 0" rpy="0 0 0" />
            <geometry>
                <mesh filename="package://robot_arm/meshes/Link_2.STL" />
            </geometry>
        </collision>
    </link>
    <joint name="Joint_2" type="revolute">
        <origin xyz="0.044 0 0.0465" rpy="0 0 0" />
        <parent link="Link_1" />
        <child link="Link_2" />
        <axis xyz="-1 0 0" />
        <limit lower="-3.14" upper="3.14" effort="100" velocity="100" />
    </joint>
    <link name="Link_3">
        <inertial>
            <origin xyz="-0.0342625302290131 -8.54393827617872E-07 0.130570556496791" rpy="0 0 0" />
            <mass value="0.368301492556341" />
            <inertia ixx="0.000284350975876608" ixy="1.99589868481762E-09" ixz="2.06902979779557E-06" iyy="0.000231576501898137" iyz="-3.41441474085351E-08" izz="0.00020347402203542" />
        </inertial>
        <visual>
            <origin xyz="0 0 0" rpy="0 0 0" />
            <geometry>
                <mesh filename="package://robot_arm/meshes/Link_3.STL" />
            </geometry>
            <material name="">
                <color rgba="0.749019607843137 0.0196078431372549 0.0352941176470588 1" />
            </material>
        </visual>
        <collision>
            <origin xyz="0 0 0" rpy="0 0 0" />
            <geometry>
                <mesh filename="package://robot_arm/meshes/Link_3.STL" />
            </geometry>
        </collision>
    </link>
    <joint name="Joint_3" type="revolute">
        <origin xyz="0 0 0.211" rpy="0 0 0" />
        <parent link="Link_2" />
        <child link="Link_3" />
        <axis xyz="-1 0 0" />
        <limit lower="-3.14" upper="3.14" effort="100" velocity="100" />
    </joint>
    <link name="Link_4">
        <inertial>
            <origin xyz="0.0279097628469686 1.05492889386494E-06 0.000741999532285043" rpy="0 0 0" />
            <mass value="0.229125165376225" />
            <inertia ixx="0.000131116825625379" ixy="2.407566633754E-08" ixz="-5.24425161186352E-06" iyy="0.000108737830933017" iyz="-5.32181525503191E-10" izz="0.000136962636362692" />
        </inertial>
        <visual>
            <origin xyz="0 0 0" rpy="0 0 0" />
            <geometry>
                <mesh filename="package://robot_arm/meshes/Link_4.STL" />
            </geometry>
            <material name="">
                <color rgba="1 1 1 1" />
            </material>
        </visual>
        <collision>
            <origin xyz="0 0 0" rpy="0 0 0" />
            <geometry>
                <mesh filename="package://robot_arm/meshes/Link_4.STL" />
            </geometry>
        </collision>
    </link>
    <joint name="Joint_4" type="revolute">
        <origin xyz="-0.0041003 0 0.1945" rpy="0 0 0" />
        <parent link="Link_3" />
        <child link="Link_4" />
        <axis xyz="1 0 0" />
        <limit lower="-3.14" upper="3.14" effort="100" velocity="100" />
    </joint>
    <link name="Link_5">
        <inertial>
            <origin xyz="0.000517900737938733 4.3776640414793E-05 0.032331216650774" rpy="0 0 0" />
            <mass value="0.199706758026391" />
            <inertia ixx="0.000126934835025011" ixy="-9.48676769820221E-09" ixz="-5.09905639766148E-06" iyy="9.85451693816129E-05" iyz="-1.08669959041328E-07" izz="0.000113330240712783" />
        </inertial>
        <visual>
            <origin xyz="0 0 0" rpy="0 0 0" />
            <geometry>
                <mesh filename="package://robot_arm/meshes/Link_5.STL" />
            </geometry>
            <material name="">
                <color rgba="0.00784313725490196 0.0117647058823529 1 1" />
            </material>
        </visual>
        <collision>
            <origin xyz="0 0 0" rpy="0 0 0" />
            <geometry>
                <mesh filename="package://robot_arm/meshes/Link_5.STL" />
            </geometry>
        </collision>
    </link>
    <joint name="Joint_5" type="revolute">
        <origin xyz="0.0396 0 0.0379" rpy="0 0 0" />
        <parent link="Link_4" />
        <child link="Link_5" />
        <axis xyz="0 0 1" />
        <limit lower="-3.14" upper="3.14" effort="100" velocity="100" />
    </joint>
    <link name="Link_6">
        <inertial>
            <origin xyz="0.0093015 -8.3655E-07 0.001069" rpy="0 0 0" />
            <mass value="0.060816" />
            <inertia ixx="3.898E-05" ixy="3.5762E-10" ixz="-1.8499E-07" iyy="2.3062E-05" iyz="9.6148E-10" izz="2.3064E-05" />
        </inertial>
        <visual>
            <origin xyz="0 0 0" rpy="0 0 0" />
            <geometry>
                <mesh filename="package://robot_arm/meshes/Link_6.STL" />
            </geometry>
            <material name="">
                <color rgba="0.79216 0.81961 0.93333 1" />
            </material>
        </visual>
        <collision>
            <origin xyz="0 0 0" rpy="0 0 0" />
            <geometry>
                <mesh filename="package://robot_arm/meshes/Link_6.STL" />
            </geometry>
        </collision>
    </link>
    <joint name="Joint_6" type="revolute">
        <origin xyz="0.0379 0 0.0396" rpy="0 0 0" />
        <parent link="Link_5" />
        <child link="Link_6" />
        <axis xyz="1 0 0" />
        <limit lower="-3.14" upper="3.14" effort="100" velocity="100" />
    </joint>
    <transmission name="trans_Joint_1">
        <type>transmission_interface/SimpleTransmission</type>
        <joint name="Joint_1">
            <hardwareInterface>hardware_interface/PositionJointInterface</hardwareInterface>
        </joint>
        <actuator name="Joint_1_motor">
            <hardwareInterface>hardware_interface/PositionJointInterface</hardwareInterface>
            <mechanicalReduction>1</mechanicalReduction>
        </actuator>
    </transmission>
    <transmission name="trans_Joint_2">
        <type>transmission_interface/SimpleTransmission</type>
        <joint name="Joint_2">
            <hardwareInterface>hardware_interface/PositionJointInterface</hardwareInterface>
        </joint>
        <actuator name="Joint_2_motor">
            <hardwareInterface>hardware_interface/PositionJointInterface</hardwareInterface>
            <mechanicalReduction>1</mechanicalReduction>
        </actuator>
    </transmission>
    <transmission name="trans_Joint_3">
        <type>transmission_interface/SimpleTransmission</type>
        <joint name="Joint_3">
            <hardwareInterface>hardware_interface/PositionJointInterface</hardwareInterface>
        </joint>
        <actuator name="Joint_3_motor">
            <hardwareInterface>hardware_interface/PositionJointInterface</hardwareInterface>
            <mechanicalReduction>1</mechanicalReduction>
        </actuator>
    </transmission>
    <transmission name="trans_Joint_4">
        <type>transmission_interface/SimpleTransmission</type>
        <joint name="Joint_4">
            <hardwareInterface>hardware_interface/PositionJointInterface</hardwareInterface>
        </joint>
        <actuator name="Joint_4_motor">
            <hardwareInterface>hardware_interface/PositionJointInterface</hardwareInterface>
            <mechanicalReduction>1</mechanicalReduction>
        </actuator>
    </transmission>
    <transmission name="trans_Joint_5">
        <type>transmission_interface/SimpleTransmission</type>
        <joint name="Joint_5">
            <hardwareInterface>hardware_interface/PositionJointInterface</hardwareInterface>
        </joint>
        <actuator name="Joint_5_motor">
            <hardwareInterface>hardware_interface/PositionJointInterface</hardwareInterface>
            <mechanicalReduction>1</mechanicalReduction>
        </actuator>
    </transmission>
    <transmission name="trans_Joint_6">
        <type>transmission_interface/SimpleTransmission</type>
        <joint name="Joint_6">
            <hardwareInterface>hardware_interface/PositionJointInterface</hardwareInterface>
        </joint>
        <actuator name="Joint_6_motor">
            <hardwareInterface>hardware_interface/PositionJointInterface</hardwareInterface>
            <mechanicalReduction>1</mechanicalReduction>
        </actuator>
    </transmission>
    <gazebo>
        <plugin name="gazebo_ros_control">
            <robotNamespace>/</robotNamespace>
        </plugin>
    </gazebo>
</robot>

